Workbook

Sheet frente (2)
A1: 1 | B1: 2 | C1: 3 | D1: 4 | E1: 5 | F1: 11
A2: CODIGO | B2: DESCRIPCION | C2: PRECIO | D2: UN x CAJA | E2: FILTRO | F2: STOCK FUERA | G2: Posición | H2: NO HAY | I2: NO | J2: POCO | K2: X
A3: 11950 | B3: Barredora Supra-sweeper | C3: 36909.435 | D3: 5 | E3: 2QA115N | G3: 1
A4: 41650 | B4: Limpia vidrios cabino | C4: 7086.09 | D4: 10 | E4: 2Q ENTRO | G4: 2
A5: 51320 | B5: Limpia vidrios 3 en 1 | C5: 17205.65 | D5: 6 | E5: 2QAE11 | G5: 3
A6: 51325 | B6: Repuesto para 51320 | C6: 6870.27 | D6: 6 | E6: 2Pasillo341N | G6: 4
A7: 51425 | B7: Limpia vidrios Powerslide 28cm(51420) | C7: 6846.083 | D7: 6 | E7: 2QAE21 | G7: 5
A8: 51522 | B8: Limpia vidrios Powerslide 40cm(51520) | C8: 8201.16 | D8: 6 | E8: 2Q ENTRO | G8: 6
A9: 51104 | B9: Limpiador de ventanas con cepillo y cabo telescópico | C9: 23020.8 | D9: 6 | E9: 2Q ENTRO | G9: 7
A10: 52000 | B10: Balde Combi 12 litros | C10: 12524.346 | D10: 1 | E10: NO HAY | G10: 8
A11: 52001 | B11: Organizador para Balde Combi | C11: 14860.978 | D11: 1 | E11: 2Q | G11: 9
A12: 52014 | B12: Set CLEAN TWIST System M 20 litros | C12: 75025.567 | D12: 1 | E12: 2Q | G12: 10
A13: 55320 | B13: Repuesto para 52014 | C13: 11006.82 | D13: 6 | E13: PAS ENTRO | G13: 11
A14: 55356 | B14: Set mopa Combi M con palo de tres piezas, cubo de 12 litros y prensa Combi | C14: 50642.258 | D14: 1 | E14: 2Q | G14: 12
... A61: 52123 | B61: Repuesto para mopa 52120 microdúo | C61: 12995.385 | D61: 6 | E61: 2Q | G61: 59
A62: 52103 | B62: Set de ruedas para Clean Twist Ergo | C62: 21941.7 | E62: 2Q | G62: 60
A63: 52110 | B63: Set Power Mope 3 en 1 | C63: 43607.63 | E63: 2Q | G63: 61
A64: 56421 | B64: Escurridor doble goma 45cm Squeege con mango regulable (80-137cm) | C64: 22325.38 | E64: 2Q | G64: 62
A65: 56422 | B65: Cabezal escurridor Squeege | C65: 15718.89 | E65: 2Q | G65: 63
A66: 51127 | B66: Limpia vidrios y marcos Cleaner S micro dúo | C66: 15862.77 | E66: 2Q | G66: 64
A67: 51128 | B67: Repuesto Limpia vidrios 51127 de microfibra con finas cerdas especiales ligeramente elevadas | C67: 5935.05 | E67: 2PASILLO | G67: 65
A68: 51163 | B68: Limpia ventanas Window Masher M | C68: 13944.37 | E68: 2Q | G68: 66
A69: 51164 | B69: Repuesto Limpia ventans Window Masher M (2 fibras) | C69: 7613.65 | E69: 2PASILLO | G69: 67
A70: 45310 | B70: Corbatero | C70: 20866.486 | E70: 2Q | G70: 68
A71: 71820 | B71: Manguero tabla de planchar | C71: 33368.17 | D71: 5 | E71: 2Final1 | G71: 69
A72: 72576 | B72: Tabla de planchar 110x30 | C72: 69086.38 | D72: 1 | E72: C712 | G72: 70
A73: 72577 | B73: Tabla de planchar 120x38 | C73: 79361.81 | D73: 1 | E73: C711 | G73: 71
A74: 71600 | B74: Funda para tablas de planchar Cotton Classic L/Universal | C74: 19172.01 | D74: 4 | E74: 2FINAL | G74: 72
A75: 71603 | B75: Funda de tabla de planchar metalizada, hasta 125x40cm | C75: 19723.55 | D75: 4 | E75: 2Final | F75: 2APARED | G75: 73
A76: 71604 | B76: Funda de tabla de planchar metalizada, hasta 140x45cm | C76: 20850.61 | D76: 4 | E76: 2Final | F76: 2APARED | G76: 74
A77: 71597 | B77: Funda para tabla de planchar small | C77: 11414.48 | D77: 10 | E77: 2FINAL | F77: 2APARED | G77: 75
A78: 71598 | B78: Funda tabla de planchar medium | C78: 12901.24 | D78: 10 | E78: 2FIN ENTRO | G78: 76
A79: 76012 | B79: Funda tabla planchar M Air Active con funciones especiales de vapor, inflado, succión y aspiración | C79: 42120.87 | E79: 2FINAL | G79: 77
A80: 71613 | B80: Funda tabla planchar S/M con perforaciones especiales para mejor distribución de vapor | C80: 29807.14 | E80: NO HAY | G80: 78
A81: 71615 | B81: Funda tabla planchar L/Universal con perforaciones especiales para mejor distribución de vapor | C81: 33595.98 | E81: 2FINAL | G81: 79
A82: 72583 | B82: Tabla de planchar de mesa 73x30 Air Board | C82: 40226.45 | D82: 1 | E82: E72 | F82: E1032 | G82: 80
A83: 72584 | B83: Tabla de planchar AirBoard Compact 110x30 | C83: 100164.46 | D83: 1 | E83: C612 | G83: 81
A84: 72585 | B84: Tabla de planchar AirBoard Compact 120x38 | C84: 105703.84 | D84: 1 | E84: C513/ C611 | G84: 82
A85: 72565 | B85: Tabla de planchar Air Board Express M Solid | C85: 156265.67 | D85: 1 | E85: C512 | G85: 83
A86: 72567 | B86: Tabla planchar Air Board Large solid (130x38) | C86: 163123.95 | D86: 1 | E86: B311/ C511 | G86: 84
...

Sheet frente
A1: 1 | B1: 2 | C1: 3 | D1: 4 | E1: 5 | F1: 11 | L1: NO BORRAR
A2: CODIGO | B2: DESCRIPCION | C2: PRECIO | D2: UN x CAJA | E2: FILTRO | F2: STOCK FUERA | G2: Posición1 | H2: No hay | I2: NO | J2: POCO | K2: X | L2: 21 07 | M2: 46223
A3: 11950 | B3: Barredora Supra-sweeper | C3: 36909.435 | D3: 5 | E3: 2Q213 | F3: 0 | G3: 1 | L3: 489 | M3: 490
A4: 41650 | B4: Limpia vidrios cabino | C4: 7086.09 | D4: 10 | E4: 2QE412 | F4: 2BÑP | G4: 2 | L4: 505 | M4: 523
A5: 51320 | B5: Limpia vidrios 3 en 1 | C5: 17205.65 | D5: 6 | E5: 2QE311 | F5: 2QE441 | G5: 3 | L5: 500 | M5: 524
A6: 51325 | B6: Repuesto para 51320 | C6: 6870.27 | D6: 6 | E6: 2P342 | F6: 0 | G6: 4 | L6: 484 | M6: 486
A7: 51425 | B7: Limpia vidrios Powerslide 28cm(51420) | C7: 6846.083 | D7: 6 | E7: 2QE331 | F7: 0 | G7: 5 | L7: 503 | M7: 525
A8: 51522 | B8: Limpia vidrios Powerslide 40cm(51520) | C8: 8201.16 | D8: 6 | E8: 2QE322 | F8: 0 | G8: 6 | L8: 502 | M8: 526
A9: 51104 | B9: Limpiador de ventanas con cepillo y cabo telescópico | C9: 23020.8 | D9: 6 | E9: NO HAY | F9: 0 | G9: 7 | L9: 718 | M9: 731
A10: 52000 | B10: Balde Combi 12 litros | C10: 12524.346 | D10: 1 | E10: NO HAY | F10: 0 | G10: 8 | L10: 719 | M10: 732
A11: 52001 | B11: Organizador para Balde Combi | C11: 14860.978 | D11: 1 | E11: 2QP5 | F11: 0 | G11: 9 | L11: 515 | M11: 491
A12: 52014 | B12: Set CLEAN TWIST System M 20 litros | C12: 75025.567 | D12: 1 | E12: 2QP1 | F12: 0 | G12: 10 | L12: 512 | M12: 492
A13: 55320 | B13: Repuesto para 52014 | C13: 11006.82 | D13: 6 | E13: NO HAY | F13: 0 | G13: 11 | L13: 720 | M13: 473
A14: 55356 | B14: Set mopa Combi M con palo de tres piezas, cubo de 12 litros y prensa Combi | C14: 50642.258 | D14: 1 | E14: NO HAY | F14: 0 | G14: 12 | L14: 721 | M14: 493
A15: 55321 | B15: Funda de lavado Clean Twist/Combi M extra soft para 55356 | C15: 11006.82 | D15: 6 | E15: 2P241 | F15: 0 | G15: 13 | L15: 477 | M15: 480
A16: 55413 | B16: Set Rotation Disc Mop Ergo | C16: 77270.1 | D16: 1 | E16: 2QR133 | F16: 2QP2 2QE251 | G16: 14 | L16: 523 | M16: 508
A17: 55515 | B17: Set Power Clean con mopa de regalo | C17: 79008.65 | D17: 1 | E17: 2QP3 | F17: 0 | G17: 15 | L17: 513 | M17: 494
A18: 56673 | B18: Mango telescópico de 0,75 a 1,35mts. Con función Easy Click | C18: 12617.936 | D18: 6 | E18: 2QR222 | F18: 0 | G18: 16 | L18: 531 | M18: 532
A19: 56415 | B19: Escoba de goma Supra con cabo extensible | C19: 26181.88 | D19: 6 | E19: NO HAY | F19: 0 | G19: 17 | L19: 722 | M19: 495
A20: 56671 | B20: Escoba de goma con Click System | C20: 13759.82 | D20: 4 | E20: 2P | F20: 0 | G20: 18 | L20: 463 | M20: 474
A21: 45032 | B21: Cabezal de escobillón Xtra Clean de 30cm | C21: 14148.2 | D21: 3 | E21: 2QR216 | F21: 0 | G21: 19 | L21: 528 | M21: 496
A22: 45033 | B22: Cabezal de escobillón para parquet Xtra Clean de 30cm | C22: 14475.2 | D22: 3 | E22: 2QR217 | F22: 0 | G22: 20 | L22: 529 | M22: 509
A23: 52111 | B23: Soporte organización escobero Click System | C23: 25931.1 | D23: 8 | E23: 2QBUCHE | F23: 0 | G23: 21 | L23: 490 | M23: 510
A24: 41404 | B24: Pala con escoba | C24: 25766.51 | D24: 4 | E24: 2QR224 | F24: 2BÑM | G24: 22 | L24: 533 | M24: 533
A25: 41405 | B25: Pala con escoba | C25: 35460.084 | D25: 4 | E25: 2QR225 | F25: 2QBUCHE | G25: 23 | L25: 534 | M25: 534
A26: 41401 | B26: Set de escoba de mano y pala Classic | C26: 11870.1 | D26: 3 | E26: 2QE421 | F26: 2QE443 | G26: 24 | L26: 506 | M26: 535
A27: 41410 | B27: Set de escoba de mano con pala recogedora | C27: 20287.08 | D27: 3 | E27: 2QE431 | F27: 2QE341 | G27: 25 | L27: 509 | M27: 531
A28: 55243 | B28: Escoba de espuma Soft & Easy con cabo telescópico | C28: 21462.1 | D28: 6 | E28: 2QR111 | F28: 0 | G28: 26 | L28: 518 | M28: 511
A29: 55244 | B29: Repuesto para escoba Soft | C29: 5863.11 | D29: 6 | E29: 2P321 | F29: 0 | G29: 27 | L29: 480 | M29: 484
A30: 41524 | B30: Cepillo para esquinas Dusty (sin cabo) | C30: 14136.21 | D30: 6 | E30: 2QR114 | F30: 0 | G30: 28 | L30: 520 | M30: 527
A31: 41520 | B31: Cepillo de microfibras super absorbente 38cm Duster | C31: 9580.01 | D31: 6 | E31: 2QR211 | F31: 0 | G31: 29 | L31: 524 | M31: 528
A32: 41701 | B32: Limpiador 360°, especial para grifería Flexipad (sin cabo) | C32: 9460.11 | D32: 6 | E32: 2QE422 | F32: 0 | G32: 30 | L32: 507 | M32: 522
A33: 41702 | B33: Repuesto para limpiador 360° Flexipad 41701 | C33: 5469.0858 | D33: 5 | E33: 2P322 | F33: 2P312 | G33: 31 | L33: 481 | M33: 487
A34: 55048 | B34: Mopa Profi XL micro dúo con cabo de acero | C34: 37516.71 | D34: 6 | E34: NO HAY | F34: 0 | G34: 32 | L34: 723 | M34: 497
A35: 55126 | B35: Repuesto de Funda de lavado Profi micro dúo | C35: 11714.23 | D35: 6 | E35: NO HAY | F35: 0 | G35: 33 | L35: 724 | M35: 485
A36: 56590 | B36: Pulverizador Pico Spray Small | C36: 52376.55 | D36: 4 | E36: 2QR131 | F36: 0 | G36: 34 | L36: 521 | M36: 536
A37: 56591 | B37: Repuesto para Pico Spray Small | C37: 4021.3866 | D37: 10 | E37: 2P232 | F37: 0 | G37: 35 | L37: 474 | M37: 479
A38: 56690 | B38: Pulverizador Easy Spray XL | C38: 61895.492 | D38: 6 | E38: 2QR132 | F38: 0 | G38: 36 | L38: 522 | M38: 542
A39: 57501 | B39: Repuesto de pulverizador Easy Spray XL | C39: 11186.67 | D39: 6 | E39: 2P221 | F39: 0 | G39: 37 | L39: 472 | M39: 477
A40: 56613 | B40: Repuesto para Picobello M micro dúo | C40: 11662.673 | D40: 6 | E40: 2P111 | F40: 0 | G40: 38 | L40: 464 | M40: 489
...

Sheet Pedido 
A1: Cliente: | J1: Observaciones:
A2: Dirección: | E2: 27226 | F2: =TODAY() -> 46254
A3: Horarios de entrega: | H3: 072026
A4: Tpte: | D4: Subtotal: | F4: =SUM(F8:F9821) -> 0 | G4: Fc:
A5: Nota de pedido | F5: =-F4*E5 -> 0 | G5: Rto:
D6: Total: | F6: =SUM(F4:F5) -> 0
A7: Codigo | B7: Cant. | C7: Descripción | D7: Precio | E7: UxC | F7: Total $ | H7: Filtro | I7: Fuera
C8: =IFERROR(IF(ISBLANK(A8),"",VLOOKUP(A8,frente!A$2:D$9835,2,FALSE)),"") | D8: =IFERROR(IF(ISBLANK(A8),"",VLOOKUP(A8,frente!A$1:D$99866,3,FALSE)),"") | E8: =IFERROR(IF(ISBLANK(B8),"",VLOOKUP(A8,frente!A$2:D$9835,4,FALSE)),"") | F8: =IFERROR(IF(ISBLANK(A8),"",B8*D8),"") | H8: =IF(ISBLANK(A8),"",IF(IFERROR(IF(ISBLANK(A8),"",VLOOKUP(A8,frente!A$2:G$976,5,FALSE)),"")="","N/A",IFERROR(IF(ISBLANK(A8),"",VLOOKUP(A8,frente!A$2:G$976,5,FALSE)),""))) | I8: =IF(ISBLANK(A8),"",IF(IFERROR(IF(ISBLANK(A8),"",VLOOKUP(A8,frente!A$2:G$976,6,FALSE)),"")="","N/A",IFERROR(IF(ISBLANK(A8),"",VLOOKUP(A8,frente!A$2:G$976,6,FALSE)),"")))
C9: =IFERROR(IF(ISBLANK(A9),"",VLOOKUP(A9,frente!A$2:D$9835,2,FALSE)),"") | D9: =IFERROR(IF(ISBLANK(A9),"",VLOOKUP(A9,frente!A$1:D$99866,3,FALSE)),"") | E9: =IFERROR(IF(ISBLANK(B9),"",VLOOKUP(A9,frente!A$2:D$9835,4,FALSE)),"") | F9: =IFERROR(IF(ISBLANK(A9),"",B9*D9),"") | H9: =IF(ISBLANK(A9),"",IF(IFERROR(IF(ISBLANK(A9),"",VLOOKUP(A9,frente!A$2:G$976,5,FALSE)),"")="","N/A",IFERROR(IF(ISBLANK(A9),"",VLOOKUP(A9,frente!A$2:G$976,5,FALSE)),""))) | I9: =IF(ISBLANK(A9),"",IF(IFERROR(IF(ISBLANK(A9),"",VLOOKUP(A9,frente!A$2:G$976,6,FALSE)),"")="","N/A",IFERROR(IF(ISBLANK(A9),"",VLOOKUP(A9,frente!A$2:G$976,6,FALSE)),"")))
C10: =IFERROR(IF(ISBLANK(A10),"",VLOOKUP(A10,frente!A$2:D$9835,2,FALSE)),"") | D10: =IFERROR(IF(ISBLANK(A10),"",VLOOKUP(A10,frente!A$1:D$99866,3,FALSE)),"") | E10: =IFERROR(IF(ISBLANK(B10),"",VLOOKUP(A10,frente!A$2:D$9835,4,FALSE)),"") | F10: =IFERROR(IF(ISBLANK(A10),"",B10*D10),"") | H10: =IF(ISBLANK(A10),"",IF(IFERROR(IF(ISBLANK(A10),"",VLOOKUP(A10,frente!A$2:G$976,5,FALSE)),"")="","N/A",IFERROR(IF(ISBLANK(A10),"",VLOOKUP(A10,frente!A$2:G$976,5,FALSE)),""))) | I10: =IF(ISBLANK(A10),"",IF(IFERROR(IF(ISBLANK(A10),"",VLOOKUP(A10,frente!A$2:G$976,6,FALSE)),"")="","N/A",IFERROR(IF(ISBLANK(A10),"",VLOOKUP(A10,frente!A$2:G$976,6,FALSE)),"")))
C11: =IFERROR(IF(ISBLANK(A11),"",VLOOKUP(A11,frente!A$2:D$9835,2,FALSE)),"") | D11: =IFERROR(IF(ISBLANK(A11),"",VLOOKUP(A11,frente!A$1:D$99866,3,FALSE)),"") | E11: =IFERROR(IF(ISBLANK(B11),"",VLOOKUP(A11,frente!A$2:D$9835,4,FALSE)),"") | F11: =IFERROR(IF(ISBLANK(A11),"",B11*D11),"") | H11: =IF(ISBLANK(A11),"",IF(IFERROR(IF(ISBLANK(A11),"",VLOOKUP(A11,frente!A$2:G$976,5,FALSE)),"")="","N/A",IFERROR(IF(ISBLANK(A11),"",VLOOKUP(A11,frente!A$2:G$976,5,FALSE)),""))) | I11: =IF(ISBLANK(A11),"",IF(IFERROR(IF(ISBLANK(A11),"",VLOOKUP(A11,frente!A$2:G$976,6,FALSE)),"")="","N/A",IFERROR(IF(ISBLANK(A11),"",VLOOKUP(A11,frente!A$2:G$976,6,FALSE)),"")))
C12: =IFERROR(IF(ISBLANK(A12),"",VLOOKUP(A12,frente!A$2:D$9835,2,FALSE)),"") | D12: =IFERROR(IF(ISBLANK(A12),"",VLOOKUP(A12,frente!A$1:D$99866,3,FALSE)),"") | E12: =IFERROR(IF(ISBLANK(B12),"",VLOOKUP(A12,frente!A$2:D$9835,4,FALSE)),"") | F12: =IFERROR(IF(ISBLANK(A12),"",B12*D12),"") | H12: =IF(ISBLANK(A12),"",IF(IFERROR(IF(ISBLANK(A12),"",VLOOKUP(A12,frente!A$2:G$976,5,FALSE)),"")="","N/A",IFERROR(IF(ISBLANK(A12),"",VLOOKUP(A12,frente!A$2:G$976,5,FALSE)),""))) | I12: =IF(ISBLANK(A12),"",IF(IFERROR(IF(ISBLANK(A12),"",VLOOKUP(A12,frente!A$2:G$976,6,FALSE)),"")="","N/A",IFERROR(IF(ISBLANK(A12),"",VLOOKUP(A12,frente!A$2:G$976,6,FALSE)),"")))
C13: =IFERROR(IF(ISBLANK(A13),"",VLOOKUP(A13,frente!A$2:D$9835,2,FALSE)),"") | D13: =IFERROR(IF(ISBLANK(A13),"",VLOOKUP(A13,frente!A$1:D$99866,3,FALSE)),"") | E13: =IFERROR(IF(ISBLANK(B13),"",VLOOKUP(A13,frente!A$2:D$9835,4,FALSE)),"") | F13: =IFERROR(IF(ISBLANK(A13),"",B13*D13),"") | H13: =IF(ISBLANK(A13),"",IF(IFERROR(IF(ISBLANK(A13),"",VLOOKUP(A13,frente!A$2:G$976,5,FALSE)),"")="","N/A",IFERROR(IF(ISBLANK(A13),"",VLOOKUP(A13,frente!A$2:G$976,5,FALSE)),""))) | I13: =IF(ISBLANK(A13),"",IF(IFERROR(IF(ISBLANK(A13),"",VLOOKUP(A13,frente!A$2:G$976,6,FALSE)),"")="","N/A",IFERROR(IF(ISBLANK(A13),"",VLOOKUP(A13,frente!A$2:G$976,6,FALSE)),"")))
C14: =IFERROR(IF(ISBLANK(A14),"",VLOOKUP(A14,frente!A$2:D$9835,2,FALSE)),"") | D14: =IFERROR(IF(ISBLANK(A14),"",VLOOKUP(A14,frente!A$1:D$99866,3,FALSE)),"") | E14: =IFERROR(IF(ISBLANK(B14),"",VLOOKUP(A14,frente!A$2:D$9835,4,FALSE)),"") | F14: =IFERROR(IF(ISBLANK(A14),"",B14*D14),"") | H14: =IF(ISBLANK(A14),"",IF(IFERROR(IF(ISBLANK(A14),"",VLOOKUP(A14,frente!A$2:G$976,5,FALSE)),"")="","N/A",IFERROR(IF(ISBLANK(A14),"",VLOOKUP(A14,frente!A$2:G$976,5,FALSE)),""))) | I14: =IF(ISBLANK(A14),"",IF(IFERROR(IF(ISBLANK(A14),"",VLOOKUP(A14,frente!A$2:G$976,6,FALSE)),"")="","N/A",IFERROR(IF(ISBLANK(A14),"",VLOOKUP(A14,frente!A$2:G$976,6,FALSE)),"")))
C15: =IFERROR(IF(ISBLANK(A15),"",VLOOKUP(A15,frente!A$2:D$9835,2,FALSE)),"") | D15: =IFERROR(IF(ISBLANK(A15),"",VLOOKUP(A15,frente!A$1:D$99866,3,FALSE)),"") | E15: =IFERROR(IF(ISBLANK(B15),"",VLOOKUP(A15,frente!A$2:D$9835,4,FALSE)),"") | F15: =IFERROR(IF(ISBLANK(A15),"",B15*D15),"") | H15: =IF(ISBLANK(A15),"",IF(IFERROR(IF(ISBLANK(A15),"",VLOOKUP(A15,frente!A$2:G$976,5,FALSE)),"")="","N/A",IFERROR(IF(ISBLANK(A15),"",VLOOKUP(A15,frente!A$2:G$976,5,FALSE)),""))) | I15: =IF(ISBLANK(A15),"",IF(IFERROR(IF(ISBLANK(A15),"",VLOOKUP(A15,frente!A$2:G$976,6,FALSE)),"")="","N/A",IFERROR(IF(ISBLANK(A15),"",VLOOKUP(A15,frente!A$2:G$976,6,FALSE)),"")))
C16: =IFERROR(IF(ISBLANK(A16),"",VLOOKUP(A16,frente!A$2:D$9835,2,FALSE)),"") | D16: =IFERROR(IF(ISBLANK(A16),"",VLOOKUP(A16,frente!A$1:D$99866,3,FALSE)),"") | E16: =IFERROR(IF(ISBLANK(B16),"",VLOOKUP(A16,frente!A$2:D$9835,4,FALSE)),"") | F16: =IFERROR(IF(ISBLANK(A16),"",B16*D16),"") | H16: =IF(ISBLANK(A16),"",IF(IFERROR(IF(ISBLANK(A16),"",VLOOKUP(A16,frente!A$2:G$976,5,FALSE)),"")="","N/A",IFERROR(IF(ISBLANK(A16),"",VLOOKUP(A16,frente!A$2:G$976,5,FALSE)),""))) | I16: =IF(ISBLANK(A16),"",IF(IFERROR(IF(ISBLANK(A16),"",VLOOKUP(A16,frente!A$2:G$976,6,FALSE)),"")="","N/A",IFERROR(IF(ISBLANK(A16),"",VLOOKUP(A16,frente!A$2:G$976,6,FALSE)),"")))
C17: =IFERROR(IF(ISBLANK(A17),"",VLOOKUP(A17,frente!A$2:D$9835,2,FALSE)),"") | D17: =IFERROR(IF(ISBLANK(A17),"",VLOOKUP(A17,frente!A$1:D$99866,3,FALSE)),"") | E17: =IFERROR(IF(ISBLANK(B17),"",VLOOKUP(A17,frente!A$2:D$9835,4,FALSE)),"") | F17: =IFERROR(IF(ISBLANK(A17),"",B17*D17),"") | H17: =IF(ISBLANK(A17),"",IF(IFERROR(IF(ISBLANK(A17),"",VLOOKUP(A17,frente!A$2:G$976,5,FALSE)),"")="","N/A",IFERROR(IF(ISBLANK(A17),"",VLOOKUP(A17,frente!A$2:G$976,5,FALSE)),""))) | I17: =IF(ISBLANK(A17),"",IF(IFERROR(IF(ISBLANK(A17),"",VLOOKUP(A17,frente!A$2:G$976,6,FALSE)),"")="","N/A",IFERROR(IF(ISBLANK(A17),"",VLOOKUP(A17,frente!A$2:G$976,6,FALSE)),"")))
C18: =IFERROR(IF(ISBLANK(A18),"",VLOOKUP(A18,frente!A$2:D$9835,2,FALSE)),"") | D18: =IFERROR(IF(ISBLANK(A18),"",VLOOKUP(A18,frente!A$1:D$99866,3,FALSE)),"") | E18: =IFERROR(IF(ISBLANK(B18),"",VLOOKUP(A18,frente!A$2:D$9835,4,FALSE)),"") | F18: =IFERROR(IF(ISBLANK(A18),"",B18*D18),"") | H18: =IF(ISBLANK(A18),"",IF(IFERROR(IF(ISBLANK(A18),"",VLOOKUP(A18,frente!A$2:G$976,5,FALSE)),"")="","N/A",IFERROR(IF(ISBLANK(A18),"",VLOOKUP(A18,frente!A$2:G$976,5,FALSE)),""))) | I18: =IF(ISBLANK(A18),"",IF(IFERROR(IF(ISBLANK(A18),"",VLOOKUP(A18,frente!A$2:G$976,6,FALSE)),"")="","N/A",IFERROR(IF(ISBLANK(A18),"",VLOOKUP(A18,frente!A$2:G$976,6,FALSE)),"")))
C19: =IFERROR(IF(ISBLANK(A19),"",VLOOKUP(A19,frente!A$2:D$9835,2,FALSE)),"") | D19: =IFERROR(IF(ISBLANK(A19),"",VLOOKUP(A19,frente!A$1:D$99866,3,FALSE)),"") | E19: =IFERROR(IF(ISBLANK(B19),"",VLOOKUP(A19,frente!A$2:D$9835,4,FALSE)),"") | F19: =IFERROR(IF(ISBLANK(A19),"",B19*D19),"") | H19: =IF(ISBLANK(A19),"",IF(IFERROR(IF(ISBLANK(A19),"",VLOOKUP(A19,frente!A$2:G$976,5,FALSE)),"")="","N/A",IFERROR(IF(ISBLANK(A19),"",VLOOKUP(A19,frente!A$2:G$976,5,FALSE)),""))) | I19: =IF(ISBLANK(A19),"",IF(IFERROR(IF(ISBLANK(A19),"",VLOOKUP(A19,frente!A$2:G$976,6,FALSE)),"")="","N/A",IFERROR(IF(ISBLANK(A19),"",VLOOKUP(A19,frente!A$2:G$976,6,FALSE)),"")))
... C895: =IFERROR(IF(ISBLANK(A895),"",VLOOKUP(A895,frente!A$2:D$9835,2,FALSE)),"") | D895: =IFERROR(IF(ISBLANK(A895),"",VLOOKUP(A895,frente!A$1:D$99866,3,FALSE)),"") | E895: =IFERROR(IF(ISBLANK(B895),"",VLOOKUP(A895,frente!A$2:D$9835,4,FALSE)),"") | F895: =IFERROR(IF(ISBLANK(A895),"",B895*D895),"") | H895: =IF(ISBLANK(A895),"",IF(IFERROR(IF(ISBLANK(A895),"",VLOOKUP(A895,frente!A$2:G$976,5,FALSE)),"")="","N/A",IFERROR(IF(ISBLANK(A895),"",VLOOKUP(A895,frente!A$2:G$976,5,FALSE)),""))) | I895: =IF(ISBLANK(A895),"",IF(IFERROR(IF(ISBLANK(A895),"",VLOOKUP(A895,frente!A$2:G$976,6,FALSE)),"")="","N/A",IFERROR(IF(ISBLANK(A895),"",VLOOKUP(A895,frente!A$2:G$976,6,FALSE)),"")))

Sheet CSV
A1: . | B1: Dato Obligatorio
A2: . | B2: Dato Opcional
A3: . | B3: Dato Condicional
A4: .
A5: .
A6: ARTICULO | B6: NOMBRE ARTICULO | C6: DEPOSITO | D6: UM | E6: CANTIDAD | F6: FECHA DE ENTREGA | G6: LISTA DE PRECIO | H6: PRECIO | I6: DESCUENTO 1 | J6: DESCUENTO 2 | K6: DESCUENTO 3 | L6: DESCUENTO 4 | M6: DESCRIPCION | N6: CLASIFICACION DE PARTIDAS 1 | O6: CLASIFICACION DE PARTIDAS 2 | P6: CLASIFICACION DE PARTIDAS 3 | Q6: CLASIFICACION DE PARTIDAS 4 | R6: CLASIFICACION DE PARTIDAS 5 | S6: CLASIFICACION DE PARTIDAS 6 | T6: CLASIFICACION DE PARTIDAS 7 | U6: CLASIFICACION DE PARTIDAS 8
A7: ='Pedido '!A8 -> 0 | C7: 2 | D7: UN | E7: =+'Pedido '!B8 -> 0
A8: ='Pedido '!A9 -> 0 | C8: 2 | D8: UN | E8: =+'Pedido '!B9 -> 0
A9: ='Pedido '!A10 -> 0 | C9: 2 | D9: UN | E9: =+'Pedido '!B10 -> 0
A10: ='Pedido '!A11 -> 0 | C10: 2 | D10: UN | E10: =+'Pedido '!B11 -> 0
A11: ='Pedido '!A12 -> 0 | C11: 2 | D11: UN | E11: =+'Pedido '!B12 -> 0
A12: ='Pedido '!A13 -> 0 | C12: 2 | D12: UN | E12: =+'Pedido '!B13 -> 0
A13: ='Pedido '!A14 -> 0 | C13: 2 | D13: UN | E13: =+'Pedido '!B14 -> 0
A14: ='Pedido '!A15 -> 0 | C14: 2 | D14: UN | E14: =+'Pedido '!B15 -> 0
A15: ='Pedido '!A16 -> 0 | C15: 2 | D15: UN | E15: =+'Pedido '!B16 -> 0
A16: ='Pedido '!A17 -> 0 | C16: 2 | D16: UN | E16: =+'Pedido '!B17 -> 0
A17: ='Pedido '!A18 -> 0 | C17: 2 | D17: UN | E17: =+'Pedido '!B18 -> 0
A18: ='Pedido '!A19 -> 0 | C18: 2 | D18: UN | E18: =+'Pedido '!B19 -> 0
... A31: ='Pedido '!A32 -> 0 | C31: 2 | D31: UN | E31: =+'Pedido '!B32 -> 0
A32: ='Pedido '!A33 -> 0 | C32: 2 | D32: UN | E32: =+'Pedido '!B34 -> 0
A33: ='Pedido '!A34 -> 0 | C33: 2 | D33: UN | E33: =+'Pedido '!B35 -> 0
A34: ='Pedido '!A35 -> 0 | C34: 2 | D34: UN | E34: =+'Pedido '!B36 -> 0
A35: ='Pedido '!A36 -> 0 | C35: 2 | D35: UN | E35: =+'Pedido '!B37 -> 0
A36: ='Pedido '!A37 -> 0 | C36: 2 | D36: UN | E36: =+'Pedido '!B38 -> 0
A37: ='Pedido '!A38 -> 0 | C37: 2 | D37: UN | E37: =+'Pedido '!B39 -> 0
A38: ='Pedido '!A39 -> 0 | C38: 2 | D38: UN | E38: =+'Pedido '!B40 -> 0
A39: ='Pedido '!A40 -> 0 | C39: 2 | D39: UN | E39: =+'Pedido '!B41 -> 0
A40: ='Pedido '!A41 -> 0 | C40: 2 | D40: UN | E40: =+'Pedido '!B42 -> 0
A41: ='Pedido '!A42 -> 0 | C41: 2 | D41: UN | E41: =+'Pedido '!B43 -> 0
A42: ='Pedido '!A43 -> 0 | C42: 2 | D42: UN | E42: =+'Pedido '!B44 -> 0
A43: ='Pedido '!A44 -> 0 | C43: 2 | D43: UN | E43: =+'Pedido '!B45 -> 0
... A264: ='Pedido '!A265 -> 0 | C264: 110 | D264: UN | E264: =+'Pedido '!B266 -> 0

Sheet Hoja1
A1: 2ES11 | B1: Botella Electro Plus Blanca 500ml
A2: 2ES12 | B2: Botella Electro Plus Negra 500ml
A3: 2ES13 | B3: Botella Electro Plus Azul 500ml
A4: 2ES14 | B4: Botella Electro Plus Celeste 500ml
A5: 2ES21 | B5: Botella Electro Plus Rosa 500ml
A6: 2ES22 | B6: Botella Electro Plus Plateada 500ml
A7: 2ES23 | B7: Botella Electro Plus Blanca 750ml
A8: 2ES24 | B8: Botella Electro Plus Negra 750ml
A9: 2ES31 | B9: Botella Electro Plus Azul 750ml
A10: 2ES32 | B10: Botella Electro Plus Celeste 750ml
A11: 2ES33 | B11: Botella Electro Plus Rosa 750ml
A12: 2ES34 | B12: Botella Electro Plus Plateada 750ml
... A23: 2ES63 | B23: Tumbler Nomad Celeste 900ml
A24: 2ES64
A25: 2ES71
A26: 2ES72
A27: 2ES73
A28: 2ES74
A29: 2ES81
A30: 2ES82
A31: 2ES83
A32: 2ES84
A33: 2ES91
A34: 2ES92
A35: 2ES93
... A48: 2ES12 4

Sheet Hoja2
A1: 22081 | B1: CUCHILLO PELADOR 9 CM | C1: 12787.88 | D1: 6
A2: 22181 | B2: CUCHILLO UNIVERSAL CON SERRUCHO 13 CM | C2: 14063.18 | D2: 6
A3: 32681 | B3: CORTA MANZANAS | C3: 15303.6 | D3: 6
A4: 34581 | B4: PISA PAPAS DE ACERO INOXIDABLE | C4: 24443.25 | D4: 6
A5: 39681 | B5: PINZA DE 40 CM. | C5: 23026.25 | D5: 6
A6: 1050030 | B6: JARRA MEDIDORA 4 TAZAS (tritán) | C6: 16578.9 | D6: 6
A7: 1056988 | B7: SET X3 JARRAS MEDIDORAS (tritán) | C7: 36771.15 | D7: 6
A8: 1057961 | B8: RALLADOR CON BASE | C8: 29366.78 | D8: 6
A9: 1057962 | B9: EXPRIMIDOR DE CÍTRICOS | C9: 26807.5 | D9: 6
A10: 1060619 | B10: LIMPIA VIDRIOS DE ACERO CON SOPAPA | C10: 23026.25 | D10: 6
A11: 1066736 | B11: PORTARROLLOS DE ACERO INOXIDABLE CON SUJETADOR | C11: 39789.36 | D11: 6
A12: 1067247 | B12: VAPORIERA DE ACERO | C12: 29366.78 | D12: 6
... A54: 13362600 | B54: SET X4 CLIPS MAGNETICOS | C54: 12787.88 | D54: 6
